Traceback (most recent call last):
  File "/opt/hostedtoolcache/Python/3.10.17/x64/lib/python3.10/site-packages/jupyter_cache/executors/utils.py", line 58, in single_nb_execution
    executenb(
  File "/opt/hostedtoolcache/Python/3.10.17/x64/lib/python3.10/site-packages/nbclient/client.py", line 1319, in execute
    return NotebookClient(nb=nb, resources=resources, km=km, **kwargs).execute()
  File "/opt/hostedtoolcache/Python/3.10.17/x64/lib/python3.10/site-packages/jupyter_core/utils/__init__.py", line 165, in wrapped
    return loop.run_until_complete(inner)
  File "/opt/hostedtoolcache/Python/3.10.17/x64/lib/python3.10/asyncio/base_events.py", line 649, in run_until_complete
    return future.result()
  File "/opt/hostedtoolcache/Python/3.10.17/x64/lib/python3.10/site-packages/nbclient/client.py", line 709, in async_execute
    await self.async_execute_cell(
  File "/opt/hostedtoolcache/Python/3.10.17/x64/lib/python3.10/site-packages/nbclient/client.py", line 1062, in async_execute_cell
    await self._check_raise_for_error(cell, cell_index, exec_reply)
  File "/opt/hostedtoolcache/Python/3.10.17/x64/lib/python3.10/site-packages/nbclient/client.py", line 918, in _check_raise_for_error
    raise CellExecutionError.from_cell_and_msg(cell, exec_reply_content)
nbclient.exceptions.CellExecutionError: An error occurred while executing the following cell:
------------------
data_text = files("dask_flood_mapper.data").joinpath("wcover.nc")
wcover = xr.open_dataarray(data_text, decode_coords="all")
------------------


[0;31m---------------------------------------------------------------------------[0m
[0;31mModuleNotFoundError[0m                       Traceback (most recent call last)
Cell [0;32mIn[4], line 1[0m
[0;32m----> 1[0m data_text [38;5;241m=[39m [43mfiles[49m[43m([49m[38;5;124;43m"[39;49m[38;5;124;43mdask_flood_mapper.data[39;49m[38;5;124;43m"[39;49m[43m)[49m[38;5;241m.[39mjoinpath([38;5;124m"[39m[38;5;124mwcover.nc[39m[38;5;124m"[39m)
[1;32m      2[0m wcover [38;5;241m=[39m xr[38;5;241m.[39mopen_dataarray(data_text, decode_coords[38;5;241m=[39m[38;5;124m"[39m[38;5;124mall[39m[38;5;124m"[39m)

File [0;32m/opt/hostedtoolcache/Python/3.10.17/x64/lib/python3.10/importlib/_common.py:22[0m, in [0;36mfiles[0;34m(package)[0m
[1;32m     17[0m [38;5;28;01mdef[39;00m[38;5;250m [39m[38;5;21mfiles[39m(package):
[1;32m     18[0m     [38;5;66;03m# type: (Package) -> Traversable[39;00m
[1;32m     19[0m [38;5;250m    [39m[38;5;124;03m"""[39;00m
[1;32m     20[0m [38;5;124;03m    Get a Traversable resource from a package[39;00m
[1;32m     21[0m [38;5;124;03m    """[39;00m
[0;32m---> 22[0m     [38;5;28;01mreturn[39;00m from_package([43mget_package[49m[43m([49m[43mpackage[49m[43m)[49m)

File [0;32m/opt/hostedtoolcache/Python/3.10.17/x64/lib/python3.10/importlib/_common.py:66[0m, in [0;36mget_package[0;34m(package)[0m
[1;32m     60[0m [38;5;28;01mdef[39;00m[38;5;250m [39m[38;5;21mget_package[39m(package):
[1;32m     61[0m     [38;5;66;03m# type: (Package) -> types.ModuleType[39;00m
[1;32m     62[0m [38;5;250m    [39m[38;5;124;03m"""Take a package name or module object and return the module.[39;00m
[1;32m     63[0m 
[1;32m     64[0m [38;5;124;03m    Raise an exception if the resolved module is not a package.[39;00m
[1;32m     65[0m [38;5;124;03m    """[39;00m
[0;32m---> 66[0m     resolved [38;5;241m=[39m [43mresolve[49m[43m([49m[43mpackage[49m[43m)[49m
[1;32m     67[0m     [38;5;28;01mif[39;00m wrap_spec(resolved)[38;5;241m.[39msubmodule_search_locations [38;5;129;01mis[39;00m [38;5;28;01mNone[39;00m:
[1;32m     68[0m         [38;5;28;01mraise[39;00m [38;5;167;01mTypeError[39;00m([38;5;124mf[39m[38;5;124m'[39m[38;5;132;01m{[39;00mpackage[38;5;132;01m!r}[39;00m[38;5;124m is not a package[39m[38;5;124m'[39m)

File [0;32m/opt/hostedtoolcache/Python/3.10.17/x64/lib/python3.10/importlib/_common.py:57[0m, in [0;36mresolve[0;34m(cand)[0m
[1;32m     55[0m [38;5;28;01mdef[39;00m[38;5;250m [39m[38;5;21mresolve[39m(cand):
[1;32m     56[0m     [38;5;66;03m# type: (Package) -> types.ModuleType[39;00m
[0;32m---> 57[0m     [38;5;28;01mreturn[39;00m cand [38;5;28;01mif[39;00m [38;5;28misinstance[39m(cand, types[38;5;241m.[39mModuleType) [38;5;28;01melse[39;00m [43mimportlib[49m[38;5;241;43m.[39;49m[43mimport_module[49m[43m([49m[43mcand[49m[43m)[49m

File [0;32m/opt/hostedtoolcache/Python/3.10.17/x64/lib/python3.10/importlib/__init__.py:126[0m, in [0;36mimport_module[0;34m(name, package)[0m
[1;32m    124[0m             [38;5;28;01mbreak[39;00m
[1;32m    125[0m         level [38;5;241m+[39m[38;5;241m=[39m [38;5;241m1[39m
[0;32m--> 126[0m [38;5;28;01mreturn[39;00m [43m_bootstrap[49m[38;5;241;43m.[39;49m[43m_gcd_import[49m[43m([49m[43mname[49m[43m[[49m[43mlevel[49m[43m:[49m[43m][49m[43m,[49m[43m [49m[43mpackage[49m[43m,[49m[43m [49m[43mlevel[49m[43m)[49m

File [0;32m<frozen importlib._bootstrap>:1050[0m, in [0;36m_gcd_import[0;34m(name, package, level)[0m

File [0;32m<frozen importlib._bootstrap>:1027[0m, in [0;36m_find_and_load[0;34m(name, import_)[0m

File [0;32m<frozen importlib._bootstrap>:1004[0m, in [0;36m_find_and_load_unlocked[0;34m(name, import_)[0m

[0;31mModuleNotFoundError[0m: No module named 'dask_flood_mapper.data'

