Traceback (most recent call last):
  File "/opt/hostedtoolcache/Python/3.12.9/x64/lib/python3.12/site-packages/jupyter_cache/executors/utils.py", line 58, in single_nb_execution
    executenb(
  File "/opt/hostedtoolcache/Python/3.12.9/x64/lib/python3.12/site-packages/nbclient/client.py", line 1319, in execute
    return NotebookClient(nb=nb, resources=resources, km=km, **kwargs).execute()
           ^^^^^^^^^^^^^^^^^^^^^^^^^^^^^^^^^^^^^^^^^^^^^^^^^^^^^^^^^^^^^^^^^^^^^
  File "/opt/hostedtoolcache/Python/3.12.9/x64/lib/python3.12/site-packages/jupyter_core/utils/__init__.py", line 165, in wrapped
    return loop.run_until_complete(inner)
           ^^^^^^^^^^^^^^^^^^^^^^^^^^^^^^
  File "/opt/hostedtoolcache/Python/3.12.9/x64/lib/python3.12/asyncio/base_events.py", line 691, in run_until_complete
    return future.result()
           ^^^^^^^^^^^^^^^
  File "/opt/hostedtoolcache/Python/3.12.9/x64/lib/python3.12/site-packages/nbclient/client.py", line 709, in async_execute
    await self.async_execute_cell(
  File "/opt/hostedtoolcache/Python/3.12.9/x64/lib/python3.12/site-packages/nbclient/client.py", line 1062, in async_execute_cell
    await self._check_raise_for_error(cell, cell_index, exec_reply)
  File "/opt/hostedtoolcache/Python/3.12.9/x64/lib/python3.12/site-packages/nbclient/client.py", line 918, in _check_raise_for_error
    raise CellExecutionError.from_cell_and_msg(cell, exec_reply_content)
nbclient.exceptions.CellExecutionError: An error occurred while executing the following cell:
------------------
flood_output.hvplot.quadmesh(
    x="longitude",
    y="latitude",
    geo=True,
    widget_location="bottom",
    rasterize=True,
    project=True,
    clim=(0, 1),
    cmap=["rgba(0, 0, 1, 0.1)", "darkred"],
    tiles=True,
    clabel="        non-flood                                        flood",
)
------------------


[31m---------------------------------------------------------------------------[39m
[31mAttributeError[39m                            Traceback (most recent call last)
[36mCell[39m[36m [39m[32mIn[34][39m[32m, line 1[39m
[32m----> [39m[32m1[39m [43mflood_output[49m[43m.[49m[43mhvplot[49m.quadmesh(
[32m      2[39m     x=[33m"[39m[33mlongitude[39m[33m"[39m,
[32m      3[39m     y=[33m"[39m[33mlatitude[39m[33m"[39m,
[32m      4[39m     geo=[38;5;28;01mTrue[39;00m,
[32m      5[39m     widget_location=[33m"[39m[33mbottom[39m[33m"[39m,
[32m      6[39m     rasterize=[38;5;28;01mTrue[39;00m,
[32m      7[39m     project=[38;5;28;01mTrue[39;00m,
[32m      8[39m     clim=([32m0[39m, [32m1[39m),
[32m      9[39m     cmap=[[33m"[39m[33mrgba(0, 0, 1, 0.1)[39m[33m"[39m, [33m"[39m[33mdarkred[39m[33m"[39m],
[32m     10[39m     tiles=[38;5;28;01mTrue[39;00m,
[32m     11[39m     clabel=[33m"[39m[33m        non-flood                                        flood[39m[33m"[39m,
[32m     12[39m )

[36mFile [39m[32m/opt/hostedtoolcache/Python/3.12.9/x64/lib/python3.12/site-packages/xarray/core/common.py:305[39m, in [36mAttrAccessMixin.__getattr__[39m[34m(self, name)[39m
[32m    303[39m         [38;5;28;01mwith[39;00m suppress([38;5;167;01mKeyError[39;00m):
[32m    304[39m             [38;5;28;01mreturn[39;00m source[name]
[32m--> [39m[32m305[39m [38;5;28;01mraise[39;00m [38;5;167;01mAttributeError[39;00m(
[32m    306[39m     [33mf[39m[33m"[39m[38;5;132;01m{[39;00m[38;5;28mtype[39m([38;5;28mself[39m).[34m__name__[39m[38;5;132;01m!r}[39;00m[33m object has no attribute [39m[38;5;132;01m{[39;00mname[38;5;132;01m!r}[39;00m[33m"[39m
[32m    307[39m )

[31mAttributeError[39m: 'DataArray' object has no attribute 'hvplot'

